Traceback (most recent call last):
  File "C:\Users\micha\anaconda3\Lib\site-packages\pandas\core\indexes\base.py", line 3805, in get_loc
    return self._engine.get_loc(casted_key)
           ^^^^^^^^^^^^^^^^^^^^^^^^^^^^^^^^
  File "index.pyx", line 167, in pandas._libs.index.IndexEngine.get_loc
  File "index.pyx", line 196, in pandas._libs.index.IndexEngine.get_loc
  File "pandas\\_libs\\hashtable_class_helper.pxi", line 7081, in pandas._libs.hashtable.PyObjectHashTable.get_item
  File "pandas\\_libs\\hashtable_class_helper.pxi", line 7089, in pandas._libs.hashtable.PyObjectHashTable.get_item
KeyError: 33309

The above exception was the direct cause of the following exception:

Traceback (most recent call last):
  File "D:\Digit_recognizer_AI_stuff\LLM_Python_Folder\import_dataset.py", line 72, in <module>
    train(model, device, train_loader, optimizer, epoch)
  File "D:\Digit_recognizer_AI_stuff\LLM_Python_Folder\import_dataset.py", line 60, in train
    for batch_idx, (data, target) in enumerate(train_loader):
  File "C:\Users\micha\anaconda3\Lib\site-packages\torch\utils\data\dataloader.py", line 630, in __next__
    data = self._next_data()
           ^^^^^^^^^^^^^^^^^
  File "C:\Users\micha\anaconda3\Lib\site-packages\torch\utils\data\dataloader.py", line 673, in _next_data
    data = self._dataset_fetcher.fetch(index)  # may raise StopIteration
           ^^^^^^^^^^^^^^^^^^^^^^^^^^^^^^^^^^
  File "C:\Users\micha\anaconda3\Lib\site-packages\torch\utils\data\_utils\fetch.py", line 52, in fetch
    data = [self.dataset[idx] for idx in possibly_batched_index]
            ~~~~~~~~~~~~^^^^^
  File "C:\Users\micha\anaconda3\Lib\site-packages\pandas\core\frame.py", line 4102, in __getitem__
    indexer = self.columns.get_loc(key)
              ^^^^^^^^^^^^^^^^^^^^^^^^^
  File "C:\Users\micha\anaconda3\Lib\site-packages\pandas\core\indexes\base.py", line 3812, in get_loc
    raise KeyError(key) from err
KeyError: 33309
